<?xml version="1.0" encoding="utf-8"?>
<robot name="wheelchair" xmlns:xacro="http://www.ros.org/wiki/xacro">
	<xacro:include filename="$(find wheelchair_1_description)/urdf/wheelchair.gazebo"/>
	<xacro:property name = "lower" value = "-1000"/>
	<xacro:property name = "upper" value = "1000"/>
  	<link name='base_link'>
	    <visual>
	    	<oririn rpy= "0 -0 0" xyx = "-0.24919 -1.2e-05 -0.357491"/>
		    <geometry>
		    	<mesh scale=" 1 1 1" filename = "package://wheelchair_1_description/meshes/Wheelchair-base_col.STL"/>
		    </geometry>
	    </visual>
	    <collision>
        	<oririn rpy= "0 -0 0" xyx = "-0.24919 -1.2e-05 -0.357491"/>
        	<geometry>
          		<mesh scale=" 1 1 1" filename = "package://wheelchair_1_description/meshes/Wheelchair-base_col.STL"/>
        	</geometry>
      	</collision>
	    <inertial>
        	<mass value="54.78178"/>
         	<inertia ixx="0.253724" ixy="7e-06" ixz="0.022948" iyy="0.218409" iyz="7e-06" izz="0.382313"/>
 	    </inertial>
  	</link>
  
  	<link name="Left-Caster-Wheel">
	  	<visual>
	  		<origin rpy = "0 -0 0" xyz = "-0.32661 -0.24669 -0.06"/>
	  		<geometry>
	  			<mesh scale=" 1 1 1" filename = "package://wheelchair_1_description/meshes/Left-Caster-Wheel.STL"/>
	  		</geometry>
	  	</visual>
	  	<collision>
        	<origin rpy = "0 -0 0" xyz = "-0.32661 -0.24669 -0.06"/>
        		<geometry>
          			<mesh scale=" 1 1 1" filename = "package://wheelchair_1_description/meshes/Left-Caster-Wheel_col.STL"/>
        		</geometry>
     	</collision>
	  	<inertial>
        	<mass value="0.149507"/>
         	<inertia ixx="0.000176" ixy="8e-06" ixz="0.0" iyy="0.000339" iyz="0.0" izz="0.000176"/>
 	    </inertial>
  	</link>

  	<link name="Left-Caster-Yaw">
	  	<visual>
		  	<origin rpy = "0 -0 0"  xyz = "-0.35956 -0.24291 -0.1517"/>
		  	<geometry>
		  		<mesh scale=" 1 1 1" filename = "package://wheelchair_1_description/meshes/Left-Caster-Yaw.STL"/>
		  	</geometry>
		</visual>
		<collision>
          	<origin rpy = "0 -0 0" xyz = "-0.35956 -0.24291 -0.1517"/>
          	<geometry>
            	<mesh scale=" 1 1 1" filename = "package://wheelchair_1_description/meshes/Left-Caster-Yaw_col.STL"/>
          	</geometry>
      	</collision>
		<inertial>
        	<mass value="0.279084"/>
         	<inertia ixx="0.000442" ixy="1e-06" ixz="0.000123" iyy="0.000458" iyz="8e-06" izz="0.000182"/>
 	    </inertial>
 	</link>

  	<link name="Left-Wheel">
	  	<visual>
	  		<origin rpy  = "0 -0 0" xyz = "-0 -0.26808 -0.305"/>
	  		<geometry>
		  		<mesh scale=" 1 1 1" filename = "package://wheelchair_1_description/meshes/Left-Wheel.STL"/>
		  	</geometry>
	  	</visual>
	  	<collision>
        	<origin rpy  = "0 -0 0" xyz = "-0 -0.26808 -0.305"/>
        	<geometry>
          		<mesh scale=" 1 1 1" filename = "package://wheelchair_1_description/meshes/Left-Wheel_col.STL"/>
        	</geometry>
      	</collision>
	  	<inertial>
        	<mass value="2.91669"/>
         	<inertia ixx="0.112302" ixy="0" ixz="0.0" iyy="0.222779" iyz="0.0" izz="0.112302"/>
 	    </inertial>
  	</link>

  	<link name="Right-Caster-Wheel">
	  	<visual>
	  		<origin rpy = "0 -0 0" xyz = "-0.32661 0.24108 -0.06"/>
	  		<geometry>
	  			<mesh scale=" 1 1 1" filename = "package://wheelchair_1_description/meshes/Right-Caster-Wheel.STL"/>
	  		</geometry>
	  	</visual>
	  	<collision>
        	<origin rpy  = "0 -0 0" xyz = "-0.32661 0.24108 -0.06"/>
        	<geometry>
          		<mesh scale=" 1 1 1" filename = "package://wheelchair_1_description/meshes/Right-Caster-Wheel_col.STL"/>
        	</geometry>
      	</collision>
	  	<inertial>
        	<mass value="0.149507"/>
         	<inertia ixx="0.000176" ixy="8e-06" ixz="0.0" iyy="0.000339" iyz="0.0" izz="0.000176"/>
 	    </inertial>
  	</link>

  	<link name="Right-Caster-Yaw">
	  	<visual>
		  	<origin rpy = "0 -0 0" xyz = "-0.35956 0.24291 -0.1517"/>
		  	<geometry>
		  		<mesh scale=" 1 1 1" filename = "package://wheelchair_1_description/meshes/Right-Caster-Yaw.STL"/>
		  	</geometry>
		</visual>
		<collision>
        	<origin rpy = "0 -0 0" xyz = "-0.35956 0.24291 -0.1517"/>
        	<geometry>
          		<mesh scale=" 1 1 1" filename = "package://wheelchair_1_description/meshes/Right-Caster-Yaw_col.STL"/>
        	</geometry>
     	</collision>
		<inertial>
	        <mass value="0.279085"/>
	         <inertia ixx="0.000442" ixy="1e-06" ixz="0.000123" iyy="0.000458" iyz="8e-06" izz="0.000182"/>
 	    </inertial>
  	</link>

  	<link name="Right-Wheel">
	  	<visual>
	  		<origin rpy  = "0 -0 0" xyz = "0 0.26808 -0.305"/>
	  		<geometry>
		  		<mesh scale=" 1 1 1" filename = "package://wheelchair_1_description/meshes/Right-Wheel.STL"/>
		  	</geometry>
	  	</visual>
	  	<collision>
        	<origin rpy  = "0 -0 0" xyz = "0 0.26808 -0.305"/>
        	<geometry>
          		<mesh scale=" 1 1 1" filename = "package://wheelchair_1_description/meshes/Right-Wheel_col.STL"/>
        	</geometry>
      	</collision>
	  	<inertial>
	        <mass value="2.91699"/>
	        <inertia ixx="0.112302" ixy="0" ixz="0" iyy="0.222779" iyz="0" izz="0.112302"/>
 	    </inertial>
  	</link>

	<joint name="Left-Caster-Yaw-Left-Caster-Wheel" type="revolute">
	   <parent link="Left-Caster-Yaw"/>
	   <child link="Left-Caster-Wheel"/>
	   <origin xyz="-0.04295 -0.00183 -0.0917"/>
	   <axis xyz="0 1 0"/>
	   <limit effort= "100" lower = "${lower}" upper = "${upper}" velocity = "10"/>
	</joint>

	<joint name="Wheelchair-base-Left-Caster-Yaw" type="revolute">
	   <parent link="base_link"/>
	   <child link="Left-Caster-Yaw"/>
	   <origin xyz="0.35956 0.24291 0.1517"/>
	   <axis xyz="0 0 -1"/>
	   <limit effort= "100" lower = "${lower}" upper = "${upper}" velocity = "10"/>
	</joint>

	<joint name="Wheelchair_base_Left_Wheel" type="revolute">
	   <parent link="base_link"/>
	   <child link="Left-Wheel"/>
	   <origin xyz="-0 0.26808 0.305"/>
	   <axis xyz="0 1 0"/>
	   <limit effort= "100" lower = "${lower}" upper = "${upper}" velocity = "10"/>
	</joint>

	<joint name="Right-Caster-Yaw-Right-Caster-Wheel" type="revolute">
	   <parent link="Right-Caster-Yaw"/>
	   <child link="Right-Caster-Wheel"/>
	   <origin xyz="-0.04295 0.00183 -0.0917"/>
	   <axis xyz="0 1 0"/>
	   <limit effort= "100" lower = "${lower}" upper = "${upper}" velocity = "10"/>
	</joint>

	<joint name="Wheelchair-base-Right-Caster-Yaw" type="revolute">
	   <parent link="base_link"/>
	   <child link="Right-Caster-Yaw"/>
	   <origin xyz="0.35956 -0.24291 0.1517"/>
	   <axis xyz="0 0 1"/>
	   <limit effort= "100" lower = "${lower}" upper = "${upper}" velocity = "10"/>
	</joint>

	<joint name="Wheelchair_base_Right_Wheel" type="revolute">
	   <parent link="base_link"/>
	   <child link="Right-Wheel"/>
	   <origin xyz="0 -0.26808 0.305"/>
	   <axis xyz="0 1 0"/>
	   <limit effort= "100" lower = "${lower}" upper = "${upper}" velocity = "10"/>
	</joint>
	
    <transmission name="Wheelchair_base_Left_Wheel-trans">
      	<type>transmission_interface/SimpleTransmission</type>
      	<actuator name="Wheelchair_base_Left_Wheel-motor">
        	<mechanicalReduction>1</mechanicalReduction>
     	</actuator>
      	<joint name="Wheelchair_base_Left_Wheel">
        	<Interface>hardware_interface/VelocityJointInterface</Interface>
        	<!-- <Interface>hardware_interface/EffortJointInterface</Interface> -->
      	</joint>
    </transmission>

    <transmission name="Wheelchair_base_Right_Wheel-trans">
      	<type>transmission_interface/SimpleTransmission</type>
      	<actuator name="Wheelchair_base_Right_Wheel-motor">
        	<mechanicalReduction>1</mechanicalReduction>
      	</actuator>
      	<joint name="Wheelchair_base_Right_Wheel">
        	<Interface>hardware_interface/VelocityJointInterface</Interface>
        	<!-- <Interface>hardware_interface/EffortJointInterface</Interface> -->
      	</joint>
    </transmission>
</robot>